Workbook

Sheet Dashboard
B1: EMBASSY OUTREACH | LEADERSHIP DASHBOARD
B2: ="As of "&TEXT(Settings!B2,"dd mmm yyyy")&" | "&Dash_Calc!B99&" embassies across "&Dash_Calc!B107&" regions | Source: Clean_Data ("&Dash_Calc!B95&" duplicate rows removed) | Silent threshold: "&Settings!B3&" days" -> As of 06 Oct 2026 | 84 embassies across 6 regions | Source: Clean_Data (7 duplicate rows removed) | Silent threshold: 90 days
B4: EMBASSIES TRACKED | D4: ACTIVE OUTREACH | F4: ENGAGED | H4: NOT STARTED | J4: OVERDUE FOLLOW-UPS | L4: SILENT ACTIVE | N4: HIGH ENGAGEMENT | P4: RECORDS TO REVIEW
B5: =Dash_Calc!B99 -> 84 | D5: =Dash_Calc!B100 -> 59 | F5: =Dash_Calc!B101 -> 19 | H5: =Dash_Calc!B102 -> 10 | J5: =Dash_Calc!B103 -> 30 | L5: =Dash_Calc!B104 -> 13 | N5: =Dash_Calc!B105 -> 17 | P5: =Dash_Calc!B106 -> 53
B7: ="in "&Dash_Calc!B107&" regions" -> in 6 regions | D7: =TEXT(Dash_Calc!B100/Dash_Calc!B99,"0%")&" of portfolio" -> 70% of portfolio | F7: =TEXT(Dash_Calc!B101/Dash_Calc!B100,"0%")&" of active" -> 32% of active | H7: =TEXT(Dash_Calc!B102/Dash_Calc!B99,"0%")&" of portfolio" -> 12% of portfolio | J7: =TEXT(Dash_Calc!B103/Dash_Calc!B100,"0%")&" of active" -> 51% of active | L7: ="no contact "&Settings!B3&"+ days" -> no contact 90+ days | N7: =TEXT(Dash_Calc!B105/(Dash_Calc!B99-Dash_Calc!B102),"0%")&" of started" -> 23% of started | P7: =TEXT(Dash_Calc!B106/Dash_Calc!B99,"0%")&" have data issues" -> 63% have data issues
B9: KEY TAKEAWAYS
B10: ="1. Pipeline: "&Dash_Calc!B100&" of "&Dash_Calc!B99&" embassies ("&TEXT(Dash_Calc!B100/Dash_Calc!B99,"0%")&") are in active outreach, but only "&Dash_Calc!B101&" ("&TEXT(Dash_Calc!B101/Dash_Calc!B100,"0%")&" of active) have reached Engaged status and "&Dash_Calc!B102&" have not been started." -> 1. Pipeline: 59 of 84 embassies (70%) are in active outreach, but only 19 (32% of active) have reached Engaged status and 10 have not been started.
B11: ="2. Follow-up discipline: "&Dash_Calc!B103&" active embassies are past their follow-up date ("&TEXT(Dash_Calc!B103/Dash_Calc!B100,"0%")&" of active) and "&Dash_Calc!B104&" have had no contact for "&Settings!B3&"+ days. Longest overdue: "&INDEX(Clean_Data!$B$2:$B$200,Dash_Calc!C70)&" ("&Dash_Calc!D70&" days)." -> 2. Follow-up discipline: 30 active embassies are past their follow-up date (51% of active) and 13 have had no contact for 90+ days. Longest overdue: Ethiopia (211 days).
B12: =IF(INDEX(Dash_Calc!A19:A24,MATCH(MAX(Dash_Calc!E19:E24),Dash_Calc!E19:E24,0))=INDEX(Dash_Calc!A19:A24,MATCH(MAX(Dash_Calc!G19:G24),Dash_Calc!G19:G24,0)),"3. Regions: "&INDEX(Dash_Calc!A19:A24,MATCH(MAX(Dash_Calc!E19:E24),Dash_Calc!E19:E24,0))&" has both the highest engaged rate ("&TEXT(MAX(Dash_Calc!E19:E24),"0%")&") and the highest share of overdue follow-ups ("&TEXT(MAX(Dash_Calc!G19:G24),"0%")&" of active) - its strongest relationships are the most at risk of going cold.","3. Regions: "&INDEX(Dash_Calc!A19:A24,MATCH(MAX(Dash_Calc!E19:E24),Dash_Calc!E19:E24,0))&" has the highest engaged rate ("&TEXT(MAX(Dash_Calc!E19:E24),"0%")&"); "&INDEX(Dash_Calc!A19:A24,MATCH(MAX(Dash_Calc!G19:G24),Dash_Calc!G19:G24,0))&" has the highest share of overdue follow-ups ("&TEXT(MAX(Dash_Calc!G19:G24),"0%")&" of its active embassies).") -> 3. Regions: Sub-Saharan Africa has both the highest engaged rate (40%) and the highest share of overdue follow-ups (80% of active) - its strongest relationships are the most at risk of going cold.
B13: ="4. Ownership & data: "&Dash_Calc!B84&" embassies have no owner; "&INDEX(Dash_Calc!A29:A34,MATCH(MAX(Dash_Calc!D29:D34),Dash_Calc!D29:D34,0))&" carries the most overdue follow-ups ("&MAX(Dash_Calc!D29:D34)&"). "&Dash_Calc!B93&" of "&Dash_Calc!B99&" records ("&TEXT(Dash_Calc!B93/Dash_Calc!B99,"0%")&") need data review - treat figures as indicative until confirmed." -> 4. Ownership & data: 8 embassies have no owner; Priya Nair carries the most overdue follow-ups (8). 53 of 84 records (63%) need data review - treat figures as indicative until confirmed.
B15: PIPELINE STATUS & REGIONAL SPREAD
B32: WHERE TO FOCUS: REGIONS & OWNERS
B33: Region | D33: Embassies | E33: Active | F33: Engaged | G33: Engaged % (of embassies) | H33: Overdue (active) | I33: Overdue % (of active) | J33: Silent | K33: Owner | M33: Embassies | N33: Active | O33: Overdue (active) | P33: Overdue % (of active) | Q33: Silent
B34: =Dash_Calc!A19 -> Europe | D34: =Dash_Calc!B19 -> 21 | E34: =Dash_Calc!C19 -> 14 | F34: =Dash_Calc!D19 -> 3 | G34: =Dash_Calc!E19 -> 0.14285714 | H34: =Dash_Calc!F19 -> 6 | I34: =Dash_Calc!G19 -> 0.42857143 | J34: =Dash_Calc!H19 -> 4 | K34: =Dash_Calc!A29 -> Anita Deshmukh | M34: =Dash_Calc!B29 -> 8 | N34: =Dash_Calc!C29 -> 5 | O34: =Dash_Calc!D29 -> 2 | P34: =Dash_Calc!E29 -> 0.4 | Q34: =Dash_Calc!F29 -> 1
B35: =Dash_Calc!A20 -> Asia-Pacific | D35: =Dash_Calc!B20 -> 15 | E35: =Dash_Calc!C20 -> 12 | F35: =Dash_Calc!D20 -> 3 | G35: =Dash_Calc!E20 -> 0.2 | H35: =Dash_Calc!F20 -> 7 | I35: =Dash_Calc!G20 -> 0.58333333 | J35: =Dash_Calc!H20 -> 1 | K35: =Dash_Calc!A30 -> Arjun Mehta | M35: =Dash_Calc!B30 -> 13 | N35: =Dash_Calc!C30 -> 9 | O35: =Dash_Calc!D30 -> 5 | P35: =Dash_Calc!E30 -> 0.55555556 | Q35: =Dash_Calc!F30 -> 4
B36: =Dash_Calc!A21 -> Sub-Saharan Africa | D36: =Dash_Calc!B21 -> 15 | E36: =Dash_Calc!C21 -> 10 | F36: =Dash_Calc!D21 -> 6 | G36: =Dash_Calc!E21 -> 0.4 | H36: =Dash_Calc!F21 -> 8 | I36: =Dash_Calc!G21 -> 0.8 | J36: =Dash_Calc!H21 -> 4 | K36: =Dash_Calc!A31 -> Neha Kulkarni | M36: =Dash_Calc!B31 -> 14 | N36: =Dash_Calc!C31 -> 9 | O36: =Dash_Calc!D31 -> 6 | P36: =Dash_Calc!E31 -> 0.66666667 | Q36: =Dash_Calc!F31 -> 2
B37: =Dash_Calc!A22 -> Americas | D37: =Dash_Calc!B22 -> 14 | E37: =Dash_Calc!C22 -> 11 | F37: =Dash_Calc!D22 -> 3 | G37: =Dash_Calc!E22 -> 0.21428571 | H37: =Dash_Calc!F22 -> 4 | I37: =Dash_Calc!G22 -> 0.36363636 | J37: =Dash_Calc!H22 -> 1 | K37: =Dash_Calc!A32 -> Priya Nair | M37: =Dash_Calc!B32 -> 14 | N37: =Dash_Calc!C32 -> 11 | O37: =Dash_Calc!D32 -> 8 | P37: =Dash_Calc!E32 -> 0.72727273 | Q37: =Dash_Calc!F32 -> 2
B38: =Dash_Calc!A23 -> Middle East & North Africa | D38: =Dash_Calc!B23 -> 12 | E38: =Dash_Calc!C23 -> 7 | F38: =Dash_Calc!D23 -> 3 | G38: =Dash_Calc!E23 -> 0.25 | H38: =Dash_Calc!F23 -> 1 | I38: =Dash_Calc!G23 -> 0.14285714 | J38: =Dash_Calc!H23 -> 1 | K38: =Dash_Calc!A33 -> Rahul Verma | M38: =Dash_Calc!B33 -> 13 | N38: =Dash_Calc!C33 -> 9 | O38: =Dash_Calc!D33 -> 1 | P38: =Dash_Calc!E33 -> 0.11111111 | Q38: =Dash_Calc!F33 -> 0
B39: =Dash_Calc!A24 -> South & Central Asia | D39: =Dash_Calc!B24 -> 7 | E39: =Dash_Calc!C24 -> 5 | F39: =Dash_Calc!D24 -> 1 | G39: =Dash_Calc!E24 -> 0.14285714 | H39: =Dash_Calc!F24 -> 4 | I39: =Dash_Calc!G24 -> 0.8 | J39: =Dash_Calc!H24 -> 2 | K39: =Dash_Calc!A34 -> Sameer Khan | M39: =Dash_Calc!B34 -> 14 | N39: =Dash_Calc!C34 -> 11 | O39: =Dash_Calc!D34 -> 6 | P39: =Dash_Calc!E34 -> 0.54545455 | Q39: =Dash_Calc!F34 -> 3
B40: =Dash_Calc!A25 -> Total | D40: =Dash_Calc!B25 -> 84 | E40: =Dash_Calc!C25 -> 59 | F40: =Dash_Calc!D25 -> 19 | G40: =Dash_Calc!E25 -> 0.22619048 | H40: =Dash_Calc!F25 -> 30 | I40: =Dash_Calc!G25 -> 0.50847458 | J40: =Dash_Calc!H25 -> 13 | K40: =Dash_Calc!A35 -> Unassigned | M40: =Dash_Calc!B35 -> 8 | N40: =Dash_Calc!C35 -> 5 | O40: =Dash_Calc!D35 -> 2 | P40: =Dash_Calc!E35 -> 0.4 | Q40: =Dash_Calc!F35 -> 1
K41: =Dash_Calc!A36 -> Total | M41: =Dash_Calc!B36 -> 84 | N41: =Dash_Calc!C36 -> 59 | O41: =Dash_Calc!D36 -> 30 | P41: =Dash_Calc!E36 -> 0.50847458 | Q41: =Dash_Calc!F36 -> 13
B43: ENGAGEMENT QUALITY & CHANNELS
B60: ATTENTION REQUIRED
B61: ="Overdue follow-ups - top 10 by days overdue ("&Dash_Calc!B103&" in total)" -> Overdue follow-ups - top 10 by days overdue (30 in total) | J61: ="Silent active embassies - top 10 by days since contact ("&Dash_Calc!B104&" in total)" -> Silent active embassies - top 10 by days since contact (13 in total)
B62: # | C62: Country | E62: Status | G62: Owner | I62: Days overdue | J62: # | K62: Country | M62: Status | O62: Owner | Q62: Days silent
B63: 1 | C63: =IF(Dash_Calc!C70="","",INDEX(Clean_Data!$B$2:$B$200,Dash_Calc!C70)) -> Ethiopia | E63: =IF(Dash_Calc!C70="","",INDEX(Clean_Data!$J$2:$J$200,Dash_Calc!C70)) -> Engaged | G63: =IF(Dash_Calc!C70="","",INDEX(Clean_Data!$K$2:$K$200,Dash_Calc!C70)) -> Neha Kulkarni | I63: =IF(Dash_Calc!D70="","",Dash_Calc!D70) -> 211 | J63: 1 | K63: =IF(Dash_Calc!G70="","",INDEX(Clean_Data!$B$2:$B$200,Dash_Calc!G70)) -> Ghana | M63: =IF(Dash_Calc!G70="","",INDEX(Clean_Data!$J$2:$J$200,Dash_Calc!G70)) -> Engaged | O63: =IF(Dash_Calc!G70="","",INDEX(Clean_Data!$K$2:$K$200,Dash_Calc!G70)) -> Anita Deshmukh | Q63: =IF(Dash_Calc!H70="","",Dash_Calc!H70) -> 331
B64: 2 | C64: =IF(Dash_Calc!C71="","",INDEX(Clean_Data!$B$2:$B$200,Dash_Calc!C71)) -> Zimbabwe | E64: =IF(Dash_Calc!C71="","",INDEX(Clean_Data!$J$2:$J$200,Dash_Calc!C71)) -> Initial Contact | G64: =IF(Dash_Calc!C71="","",INDEX(Clean_Data!$K$2:$K$200,Dash_Calc!C71)) -> Arjun Mehta | I64: =IF(Dash_Calc!D71="","",Dash_Calc!D71) -> 181 | J64: 2 | K64: =IF(Dash_Calc!G71="","",INDEX(Clean_Data!$B$2:$B$200,Dash_Calc!G71)) -> Ethiopia | M64: =IF(Dash_Calc!G71="","",INDEX(Clean_Data!$J$2:$J$200,Dash_Calc!G71)) -> Engaged | O64: =IF(Dash_Calc!G71="","",INDEX(Clean_Data!$K$2:$K$200,Dash_Calc!G71)) -> Neha Kulkarni | Q64: =IF(Dash_Calc!H71="","",Dash_Calc!H71) -> 228
B65: 3 | C65: =IF(Dash_Calc!C72="","",INDEX(Clean_Data!$B$2:$B$200,Dash_Calc!C72)) -> Russian Federation | E65: =IF(Dash_Calc!C72="","",INDEX(Clean_Data!$J$2:$J$200,Dash_Calc!C72)) -> Engaged | G65: =IF(Dash_Calc!C72="","",INDEX(Clean_Data!$K$2:$K$200,Dash_Calc!C72)) -> Neha Kulkarni | I65: =IF(Dash_Calc!D72="","",Dash_Calc!D72) -> 179 | J65: 3 | K65: =IF(Dash_Calc!G72="","",INDEX(Clean_Data!$B$2:$B$200,Dash_Calc!G72)) -> Peru | M65: =IF(Dash_Calc!G72="","",INDEX(Clean_Data!$J$2:$J$200,Dash_Calc!G72)) -> Initial Contact | O65: =IF(Dash_Calc!G72="","",INDEX(Clean_Data!$K$2:$K$200,Dash_Calc!G72)) -> Priya Nair | Q65: =IF(Dash_Calc!H72="","",Dash_Calc!H72) -> 225
B66: 4 | C66: =IF(Dash_Calc!C73="","",INDEX(Clean_Data!$B$2:$B$200,Dash_Calc!C73)) -> Ireland | E66: =IF(Dash_Calc!C73="","",INDEX(Clean_Data!$J$2:$J$200,Dash_Calc!C73)) -> In Discussion | G66: =IF(Dash_Calc!C73="","",INDEX(Clean_Data!$K$2:$K$200,Dash_Calc!C73)) -> Sameer Khan | I66: =IF(Dash_Calc!D73="","",Dash_Calc!D73) -> 173 | J66: 4 | K66: =IF(Dash_Calc!G73="","",INDEX(Clean_Data!$B$2:$B$200,Dash_Calc!G73)) -> Germany | M66: =IF(Dash_Calc!G73="","",INDEX(Clean_Data!$J$2:$J$200,Dash_Calc!G73)) -> Initial Contact | O66: =IF(Dash_Calc!G73="","",INDEX(Clean_Data!$K$2:$K$200,Dash_Calc!G73)) -> Priya Nair | Q66: =IF(Dash_Calc!H73="","",Dash_Calc!H73) -> 223
B67: 5 | C67: =IF(Dash_Calc!C74="","",INDEX(Clean_Data!$B$2:$B$200,Dash_Calc!C74)) -> Germany | E67: =IF(Dash_Calc!C74="","",INDEX(Clean_Data!$J$2:$J$200,Dash_Calc!C74)) -> Initial Contact | G67: =IF(Dash_Calc!C74="","",INDEX(Clean_Data!$K$2:$K$200,Dash_Calc!C74)) -> Priya Nair | I67: =IF(Dash_Calc!D74="","",Dash_Calc!D74) -> 169 | J67: 5 | K67: =IF(Dash_Calc!G74="","",INDEX(Clean_Data!$B$2:$B$200,Dash_Calc!G74)) -> Zimbabwe | M67: =IF(Dash_Calc!G74="","",INDEX(Clean_Data!$J$2:$J$200,Dash_Calc!G74)) -> Initial Contact | O67: =IF(Dash_Calc!G74="","",INDEX(Clean_Data!$K$2:$K$200,Dash_Calc!G74)) -> Arjun Mehta | Q67: =IF(Dash_Calc!H74="","",Dash_Calc!H74) -> 222
B68: 6 | C68: =IF(Dash_Calc!C75="","",INDEX(Clean_Data!$B$2:$B$200,Dash_Calc!C75)) -> Peru | E68: =IF(Dash_Calc!C75="","",INDEX(Clean_Data!$J$2:$J$200,Dash_Calc!C75)) -> Initial Contact | G68: =IF(Dash_Calc!C75="","",INDEX(Clean_Data!$K$2:$K$200,Dash_Calc!C75)) -> Priya Nair | I68: =IF(Dash_Calc!D75="","",Dash_Calc!D75) -> 167 | J68: 6 | K68: =IF(Dash_Calc!G75="","",INDEX(Clean_Data!$B$2:$B$200,Dash_Calc!G75)) -> Russian Federation | M68: =IF(Dash_Calc!G75="","",INDEX(Clean_Data!$J$2:$J$200,Dash_Calc!G75)) -> Engaged | O68: =IF(Dash_Calc!G75="","",INDEX(Clean_Data!$K$2:$K$200,Dash_Calc!G75)) -> Neha Kulkarni | Q68: =IF(Dash_Calc!H75="","",Dash_Calc!H75) -> 218
B69: 7 | C69: =IF(Dash_Calc!C76="","",INDEX(Clean_Data!$B$2:$B$200,Dash_Calc!C76)) -> Nigeria | E69: =IF(Dash_Calc!C76="","",INDEX(Clean_Data!$J$2:$J$200,Dash_Calc!C76)) -> Engaged | G69: =IF(Dash_Calc!C76="","",INDEX(Clean_Data!$K$2:$K$200,Dash_Calc!C76)) -> Arjun Mehta | I69: =IF(Dash_Calc!D76="","",Dash_Calc!D76) -> 98 | J69: 7 | K69: =IF(Dash_Calc!G76="","",INDEX(Clean_Data!$B$2:$B$200,Dash_Calc!G76)) -> Ireland | M69: =IF(Dash_Calc!G76="","",INDEX(Clean_Data!$J$2:$J$200,Dash_Calc!G76)) -> In Discussion | O69: =IF(Dash_Calc!G76="","",INDEX(Clean_Data!$K$2:$K$200,Dash_Calc!G76)) -> Sameer Khan | Q69: =IF(Dash_Calc!H76="","",Dash_Calc!H76) -> 214
B70: 8 | C70: =IF(Dash_Calc!C77="","",INDEX(Clean_Data!$B$2:$B$200,Dash_Calc!C77)) -> Iraq | E70: =IF(Dash_Calc!C77="","",INDEX(Clean_Data!$J$2:$J$200,Dash_Calc!C77)) -> In Discussion | G70: =IF(Dash_Calc!C77="","",INDEX(Clean_Data!$K$2:$K$200,Dash_Calc!C77)) -> Sameer Khan | I70: =IF(Dash_Calc!D77="","",Dash_Calc!D77) -> 91 | J70: 8 | K70: =IF(Dash_Calc!G77="","",INDEX(Clean_Data!$B$2:$B$200,Dash_Calc!G77)) -> Nigeria | M70: =IF(Dash_Calc!G77="","",INDEX(Clean_Data!$J$2:$J$200,Dash_Calc!G77)) -> Engaged | O70: =IF(Dash_Calc!G77="","",INDEX(Clean_Data!$K$2:$K$200,Dash_Calc!G77)) -> Arjun Mehta | Q70: =IF(Dash_Calc!H77="","",Dash_Calc!H77) -> 141
B71: 9 | C71: =IF(Dash_Calc!C78="","",INDEX(Clean_Data!$B$2:$B$200,Dash_Calc!C78)) -> Denmark | E71: =IF(Dash_Calc!C78="","",INDEX(Clean_Data!$J$2:$J$200,Dash_Calc!C78)) -> Meeting Scheduled | G71: =IF(Dash_Calc!C78="","",INDEX(Clean_Data!$K$2:$K$200,Dash_Calc!C78)) -> Sameer Khan | I71: =IF(Dash_Calc!D78="","",Dash_Calc!D78) -> 86 | J71: 9 | K71: =IF(Dash_Calc!G78="","",INDEX(Clean_Data!$B$2:$B$200,Dash_Calc!G78)) -> Iraq | M71: =IF(Dash_Calc!G78="","",INDEX(Clean_Data!$J$2:$J$200,Dash_Calc!G78)) -> In Discussion | O71: =IF(Dash_Calc!G78="","",INDEX(Clean_Data!$K$2:$K$200,Dash_Calc!G78)) -> Sameer Khan | Q71: =IF(Dash_Calc!H78="","",Dash_Calc!H78) -> 132
B72: 10 | C72: =IF(Dash_Calc!C79="","",INDEX(Clean_Data!$B$2:$B$200,Dash_Calc!C79)) -> Bhutan | E72: =IF(Dash_Calc!C79="","",INDEX(Clean_Data!$J$2:$J$200,Dash_Calc!C79)) -> Initial Contact | G72: =IF(Dash_Calc!C79="","",INDEX(Clean_Data!$K$2:$K$200,Dash_Calc!C79)) -> Arjun Mehta | I72: =IF(Dash_Calc!D79="","",Dash_Calc!D79) -> 77 | J72: 10 | K72: =IF(Dash_Calc!G79="","",INDEX(Clean_Data!$B$2:$B$200,Dash_Calc!G79)) -> Indonesia | M72: =IF(Dash_Calc!G79="","",INDEX(Clean_Data!$J$2:$J$200,Dash_Calc!G79)) -> Initial Contact | O72: =IF(Dash_Calc!G79="","",INDEX(Clean_Data!$K$2:$K$200,Dash_Calc!G79)) -> Unassigned | Q72: =IF(Dash_Calc!H79="","",Dash_Calc!H79) -> 128
B74: DATA QUALITY SNAPSHOT & DEFINITIONS
B75: Issue | H75: Records | I75: % of records | J75: Definitions & notes
B76: =Dash_Calc!A84 -> Embassies with no owner assigned | H76: =Dash_Calc!B84 -> 8 | I76: =Dash_Calc!C84 -> 0.095238095 | J76: ="• Active = Initial Contact, In Discussion, Meeting Scheduled or Engaged (editable on Dash_Calc)." -> • Active = Initial Contact, In Discussion, Meeting Scheduled or Engaged (editable on Dash_Calc).
B77: =Dash_Calc!A85 -> Email missing or invalid | H77: =Dash_Calc!B85 -> 13 | I77: =Dash_Calc!C85 -> 0.1547619 | J77: ="• Overdue = active embassy whose next follow-up date is before "&TEXT(Settings!B2,"dd mmm yyyy")&"." -> • Overdue = active embassy whose next follow-up date is before 06 Oct 2026.
B78: =Dash_Calc!A86 -> Phone missing or invalid | H78: =Dash_Calc!B86 -> 12 | I78: =Dash_Calc!C86 -> 0.14285714 | J78: ="• Silent = active embassy with no contact for more than "&Settings!B3&" days (future-dated contacts excluded)." -> • Silent = active embassy with no contact for more than 90 days (future-dated contacts excluded).
...

Sheet Data_Quality_Review
B1: DATA QUALITY REVIEW
B2: ="Scope: Embassy Outreach Database | "&COUNTA(Raw_Data!$B$2:$B$300)&" raw rows reviewed | "&COUNTA(Clean_Data!$A$2:$A$200)&" unique records after cleaning | Reporting date: "&TEXT(Settings!B2,"dd mmm yyyy")&" | Detail of every change: Cleaning_Log, Removed_Rows" -> Scope: Embassy Outreach Database | 91 raw rows reviewed | 84 unique records after cleaning | Reporting date: 06 Oct 2026 | Detail of every change: Cleaning_Log, Removed_Rows
B4: SUMMARY OF FINDINGS
B5: ="1. Duplicates: "&COUNTA(Removed_Rows!$A$2:$A$100)&" rows removed (exact and near-duplicates); 3 original records kept but the contact needs confirming. Left in, they would have overstated the embassy count and the Engaged total." -> 1. Duplicates: 7 rows removed (exact and near-duplicates); 3 original records kept but the contact needs confirming. Left in, they would have overstated the embassy count and the Engaged total.
B6: ="2. Reliability: "&Dash_Calc!B93&" of "&Dash_Calc!B99&" records ("&TEXT(Dash_Calc!B93/Dash_Calc!B99,"0%")&") still carry at least one gap or conflict that needs owner confirmation. Dashboard figures are indicative until these are resolved." -> 2. Reliability: 53 of 84 records (63%) still carry at least one gap or conflict that needs owner confirmation. Dashboard figures are indicative until these are resolved.
B7: ="3. Highest-impact gaps: "&Dash_Calc!B84&" embassies with no owner, "&Dash_Calc!B89&" active embassies with no follow-up date, "&Dash_Calc!B87&" status-vs-activity conflicts and "&Dash_Calc!B88&" records with impossible or future dates. These directly affect overdue / silent monitoring and accountability." -> 3. Highest-impact gaps: 8 embassies with no owner, 7 active embassies with no follow-up date, 7 status-vs-activity conflicts and 7 records with impossible or future dates. These directly affect overdue / silent monitoring and accountability.
B8: ="4. Root cause: the source file has no controlled inputs - "&15&" spellings of 7 statuses, 10 region spellings, text dates and blank mandatory fields all came from free-text entry. Fixing entry (drop-downs, mandatory fields, date validation) matters more than repeated clean-ups." -> 4. Root cause: the source file has no controlled inputs - 15 spellings of 7 statuses, 10 region spellings, text dates and blank mandatory fields all came from free-text entry. Fixing entry (drop-downs, mandatory fields, date validation) matters more than repeated clean-ups.
B10: FIELD COMPLETENESS (cleaned data)
B11: Field | D11: Measured on | E11: Complete | F11: Base | G11: % complete | H11: Reading this table: "Complete" counts records where the field holds a usable value. Fields below 90% are shown in red. "Outreach started" excludes Not Started embassies; "Active" = Initial Contact, In Discussion, Meeting Scheduled, Engaged. Blank engagement level or channel on a Not Started embassy is expected and is not counted as a gap.
B12: Region populated | D12: All embassies | E12: =COUNTA(Clean_Data!$C$2:$C$200) -> 84 | F12: =Dash_Calc!B99 -> 84 | G12: =IF(F12=0,0,E12/F12) -> 1
B13: Outreach owner assigned | D13: All embassies | E13: =Dash_Calc!B99-COUNTIF(Clean_Data!$K$2:$K$200,"Unassigned") -> 76 | F13: =Dash_Calc!B99 -> 84 | G13: =IF(F13=0,0,E13/F13) -> 0.9047619
B14: Valid email address | D14: All embassies | E14: =COUNTIF(Clean_Data!$G$2:$G$200,"Yes") -> 71 | F14: =Dash_Calc!B99 -> 84 | G14: =IF(F14=0,0,E14/F14) -> 0.8452381
B15: Valid phone number | D15: All embassies | E15: =COUNTIF(Clean_Data!$I$2:$I$200,"Yes") -> 72 | F15: =Dash_Calc!B99 -> 84 | G15: =IF(F15=0,0,E15/F15) -> 0.85714286
B16: Interaction count recorded (valid) | D16: All embassies | E16: =COUNT(Clean_Data!$O$2:$O$200) -> 77 | F16: =Dash_Calc!B99 -> 84 | G16: =IF(F16=0,0,E16/F16) -> 0.91666667
B17: Last contact date recorded | D17: Outreach started | E17: =COUNTIFS(Clean_Data!$J$2:$J$200,"<>Not Started",Clean_Data!$M$2:$M$200,"<>") -> 70 | F17: =(Dash_Calc!B99-Dash_Calc!B102) -> 74 | G17: =IF(F17=0,0,E17/F17) -> 0.94594595
B18: Engagement level recorded | D18: Outreach started | E18: =(Dash_Calc!B99-Dash_Calc!B102)-COUNTIF(Clean_Data!$P$2:$P$200,"Not Recorded") -> 64 | F18: =(Dash_Calc!B99-Dash_Calc!B102) -> 74 | G18: =IF(F18=0,0,E18/F18) -> 0.86486486
B19: Next follow-up date scheduled | D19: Active embassies | E19: =COUNTIFS(Dash_Calc!$AA$2:$AA$200,1,Clean_Data!$N$2:$N$200,"<>") -> 52 | F19: =Dash_Calc!B100 -> 59 | G19: =IF(F19=0,0,E19/F19) -> 0.88135593
B21: DETAILED FINDINGS
B22: # | C22: Category | D22: Issue found | E22: Records affected | F22: % of records | G22: Severity | H22: Impact on reporting / decisions | I22: Action taken in cleaning | J22: Recommended follow-up
B23: 1 | C23: Duplicates & identity | D23: Exact duplicate rows (same ID, country and contact) | E23: =COUNTIF(Removed_Rows!$F$2:$F$100,"Exact*") -> 4 | F23: =IF(Dash_Calc!$B$99=0,0,E23/Dash_Calc!$B$99) -> 0.047619048 | G23: High | H23: Inflates the embassy total and status counts; distorts every percentage on the dashboard. | I23: Removed from Clean_Data; listed on Removed_Rows. | J23: Block duplicate IDs at entry (unique-ID validation).
B24: 2 | C24: Duplicates & identity | D24: Near-duplicates: same country, email and dates re-entered under a new ID / contact (Mexico, Ghana, Singapore) | E24: =COUNTIF(Removed_Rows!$F$2:$F$100,"Near*") -> 3 | F24: =IF(Dash_Calc!$B$99=0,0,E24/Dash_Calc!$B$99) -> 0.035714286 | G24: High | H24: One embassy counted twice with a different contact; unclear which contact is current. The 3 kept records may carry the wrong contact. | I24: Later entry removed, original kept and flagged NEAR_DUP_KEPT. | J24: Owners to confirm the correct contact for the 3 kept records.
B25: 3 | C25: Duplicates & identity | D25: Missing Embassy_ID (Senegal, USA) | E25: =COUNTIF(Clean_Data!$S$2:$S$200,"*ID_INFERRED*") -> 2 | F25: =IF(Dash_Calc!$B$99=0,0,E25/Dash_Calc!$B$99) -> 0.023809524 | G25: Medium | H25: Records cannot be reliably updated or joined to other systems. | I25: IDs inferred from sequence (EMB-060, EMB-063); flagged. | J25: Confirm the two IDs against the master list.
B26: 4 | C26: Duplicates & identity | D26: Same contact name appears under different countries (8 names, 17 records) | E26: =SUMPRODUCT((Clean_Data!$D$2:$D$200<>"")*(COUNTIF(Clean_Data!$D$2:$D$200,Clean_Data!$D$2:$D$200)>1)) -> 17 | F26: =IF(Dash_Calc!$B$99=0,0,E26/Dash_Calc!$B$99) -> 0.20238095 | G26: Low | H26: May be coincidence or a copy-paste entry error; if wrong, contact details for those embassies are unreliable. | I26: No change; observation only. | J26: Spot-check the 17 records when verifying contacts.
B27: 5 | C27: Missing information | D27: No outreach owner assigned | E27: =Dash_Calc!B84 -> 8 | F27: =IF(Dash_Calc!$B$99=0,0,E27/Dash_Calc!$B$99) -> 0.095238095 | G27: High | H27: No accountability: these embassies sit outside every owner's workload and their follow-ups can be missed. | I27: Labelled "Unassigned" (not dropped). | J27: Assign an owner to each; make Owner mandatory.
B28: 6 | C28: Missing information | D28: Active embassy with no follow-up date scheduled | E28: =COUNTIF(Clean_Data!$S$2:$S$200,"*FOLLOWUP_MISSING*") -> 7 | F28: =IF(Dash_Calc!$B$99=0,0,E28/Dash_Calc!$B$99) -> 0.083333333 | G28: High | H28: Cannot be tracked as overdue, so the true overdue count is understated. | I28: Left blank and flagged. | J28: Owners to set a next action date; make it mandatory for active status.
B29: 7 | C29: Missing information | D29: Engagement level not recorded where outreach has started | E29: =COUNTIF(Clean_Data!$S$2:$S$200,"*ENG_MISSING*") -> 10 | F29: =IF(Dash_Calc!$B$99=0,0,E29/Dash_Calc!$B$99) -> 0.11904762 | G29: Medium | H29: Engagement analysis understates both High and Low; shown as "Not Recorded" on charts. | I29: Labelled "Not Recorded"; Not Started shown as N/A. | J29: Owners to rate engagement; add a drop-down.
B30: 8 | C30: Missing information | D30: Interaction count missing, or negative (set to blank) | E30: =COUNTIF(Clean_Data!$S$2:$S$200,"*INTERACTIONS_*") -> 5 | F30: =IF(Dash_Calc!$B$99=0,0,E30/Dash_Calc!$B$99) -> 0.05952381 | G30: Medium | H30: Activity level unknown for these embassies; averages exclude them. | I30: Negative value blanked (true value unknown); missing not assumed 0. | J30: Re-capture from owners' records.
B31: 9 | C31: Missing information | D31: Email missing or malformed | E31: =Dash_Calc!B85 -> 13 | F31: =IF(Dash_Calc!$B$99=0,0,E31/Dash_Calc!$B$99) -> 0.1547619 | G31: Medium | H31: Outreach cannot be sent or confirmed by email. | I31: Original text kept; Email_Valid flag added. | J31: Obtain valid emails; add format validation.
B32: 10 | C32: Missing information | D32: Phone missing or incomplete | E32: =Dash_Calc!B86 -> 12 | F32: =IF(Dash_Calc!$B$99=0,0,E32/Dash_Calc!$B$99) -> 0.14285714 | G32: Medium | H32: Alternative channel unavailable for follow-up. | I32: Incomplete numbers cleared; valid numbers standardised. | J32: Obtain numbers; apply a single format.
B33: 11 | C33: Logical inconsistency | D33: Status conflicts with activity (Not Started but contacted; or active with 0 interactions) | E33: =COUNTIF(Clean_Data!$S$2:$S$200,"*STATUS_CONFLICT*") -> 7 | F33: =IF(Dash_Calc!$B$99=0,0,E33/Dash_Calc!$B$99) -> 0.083333333 | G33: High | H33: Status is the main pipeline measure - these records may sit in the wrong stage, so pipeline counts could be off. | I33: Kept as recorded; flagged for owner confirmation. | J33: Owners to confirm true status; add a rule linking status and interaction count.
B34: 12 | C34: Logical inconsistency | D34: Date errors: last contact before first contact (4), future-dated first / last contact (4 combined), follow-up before last contact (2) | E34: =Dash_Calc!B88 -> 7 | F34: =IF(Dash_Calc!$B$99=0,0,E34/Dash_Calc!$B$99) -> 0.083333333 | G34: High | H34: Days-since-contact and overdue logic is unreliable; future-dated contacts are excluded from the silent measure, so those embassies cannot be flagged. | I34: Kept as recorded; Days_Since_Last_Contact left blank for future dates; flagged. | J34: Correct from source (likely typing / day-month errors); add date validation.
B35: 13 | C35: Logical inconsistency | D35: Region mapping unclear (Kazakhstan under Asia-Pacific while other Central Asian states are South & Central Asia) | E35: =COUNTIF(Clean_Data!$S$2:$S$200,"*REGION_REVIEW*") -> 1 | F35: =IF(Dash_Calc!$B$99=0,0,E35/Dash_Calc!$B$99) -> 0.011904762 | G35: Low | H35: Regional totals depend on this mapping decision (1 embassy). | I35: Left as recorded; flagged. | J35: Management to agree one region mapping list.
B36: 14 | C36: Standardisation (fixed) | D36: Outreach status spelling variants (15 spellings for 7 statuses) | E36: =COUNTIF(Clean_Data!$S$2:$S$200,"*STATUS_STD*") -> 13 | F36: =IF(Dash_Calc!$B$99=0,0,E36/Dash_Calc!$B$99) -> 0.1547619 | G36: Low | H36: Without fixing, the same status would be split across several categories. | I36: Standardised to 7 statuses. | J36: Replace free text with a drop-down list.
B37: 15 | C37: Standardisation (fixed) | D37: Region spelling variants or blank region | E37: =COUNTIF(Clean_Data!$S$2:$S$200,"*REGION_STD*")+COUNTIF(Clean_Data!$S$2:$S$200,"*REGION_FILLED*") -> 13 | F37: =IF(Dash_Calc!$B$99=0,0,E37/Dash_Calc!$B$99) -> 0.1547619 | G37: Low | H37: Regional views would be fragmented or incomplete. | I37: Mapped to 6 regions; blanks filled from country. | J37: Use a country-to-region lookup list.
B38: 16 | C38: Standardisation (fixed) | D38: Country name case / spacing variants | E38: =COUNTIF(Clean_Data!$S$2:$S$200,"*COUNTRY_STD*") -> 3 | F38: =IF(Dash_Calc!$B$99=0,0,E38/Dash_Calc!$B$99) -> 0.035714286 | G38: Low | H38: Country-level counts and lookups would fail. | I38: Trimmed and title-cased. | J38: Use a standard country list.
B39: 17 | C39: Standardisation (fixed) | D39: Dates stored as text (mixed dd/mm/yyyy and yyyy-mm-dd) | E39: =COUNTIF(Clean_Data!$S$2:$S$200,"*DATE_TEXT*") -> 8 | F39: =IF(Dash_Calc!$B$99=0,0,E39/Dash_Calc!$B$99) -> 0.095238095 | G39: Low | H39: Text dates cannot be sorted or used in date calculations. Day-first was assumed for dd/mm/yyyy. | I39: Converted to real dates. | J39: Enforce a date format on entry.
B40: Note: a record can carry several issues, so counts overlap and do not add up to a row total. "Records needing review" on the Dashboard counts each record once (any gap / conflict flag; cosmetic fixes excluded). Severity is a judgement based on effect on decisions: High = changes a headline number or accountability; Medium = weakens analysis; Low = cosmetic or already fixed.
B42: RECORD-LEVEL WORKLIST: HIGH-SEVERITY RECORDS TO CONFIRM FIRST
B43: # | C43: Embassy ID | D43: Country | Status | E43: Outreach owner | H43: What to confirm | I43: Issue type | J43: Next step
B44: 1 | C44: EMB-006 | D44: =IFERROR(INDEX(Clean_Data!$B$2:$B$200,MATCH($C44,Clean_Data!$A$2:$A$200,0)),"not found")&" | "&IFERROR(INDEX(Clean_Data!$J$2:$J$200,MATCH($C44,Clean_Data!$A$2:$A$200,0)),"not found") -> Netherlands | Not Started | E44: =IFERROR(INDEX(Clean_Data!$K$2:$K$200,MATCH($C44,Clean_Data!$A$2:$A$200,0)),"not found") -> Neha Kulkarni | H44: Status says Not Started but a last contact date and 2 interactions are recorded | I44: Status conflict | J44: =IF(IFERROR(INDEX(Clean_Data!$K$2:$K$200,MATCH($C44,Clean_Data!$A$2:$A$200,0)),"not found")="Unassigned","Manager: assign an owner, then confirm","Owner to confirm and correct in the source") -> Owner to confirm and correct in the source
...

Sheet Settings
A1: Settings (inputs used by formulas across the workbook)
A2: As-of date: | B2: 46301 | C2: ~ Reporting date for overdue / silent calculations. Set to the date of the review meeting; everything recalculates.
A3: Silent threshold (days): | B3: 90 | C3: ~ An active embassy with no contact for more than this many days is flagged "silent".
A5: Legend
A6: Blue text on yellow = input you can change
A7: Green-shaded columns on Clean_Data = formulas driven by the as-of date
A8: Raw_Data = untouched original.
A9: Clean_Data = analysis table (84 rows).
A10: Removed_Rows = 7 duplicates excluded.

Sheet Clean_Data
A1: Embassy_ID | B1: Country | C1: Region | D1: Contact_Person | E1: Designation | F1: Email | G1: Email_Valid | H1: Phone_Clean | I1: Phone_Valid | J1: Outreach_Status | K1: Outreach_Owner | L1: First_Contact_Date | M1: Last_Contact_Date | N1: Next_Followup_Date | O1: Interactions | P1: Engagement_Level | Q1: Channel | R1: Remarks | S1: Issue_Flags | T1: Source_Row | U1: Days_Since_Last_Contact | V1: Followup_Overdue | W1: Silent_Active
A2: EMB-001 | B2: France | C2: Europe | D2: Mei Schmidt | E2: Counsellor (Public Affairs) | F2: mei.schmidt@france.embassy.example | G2: Yes | H2: +91 91399 86987 | I2: Yes | J2: Not Started | K2: Neha Kulkarni | O2: 0 | P2: N/A (Not Started) | Q2: N/A (Not Started) | R2: Priority list - Q4 | S2: COUNTRY_STD | T2: 2 | U2: =IF(OR(M2="",M2>Settings!$B$2),"",Settings!$B$2-M2) | V2: =IF(AND(N2<>"",N2<Settings!$B$2,J2<>"Closed"),"Yes","No") -> No | W2: =IF(AND(OR(J2="Initial Contact",J2="In Discussion",J2="Meeting Scheduled",J2="Engaged"),ISNUMBER(U2),U2>Settings!$B$3),"Yes","No") -> No
A3: EMB-002 | B3: Germany | C3: Europe | D3: Stefan Haddad | E3: Commercial Counsellor | F3: stefan.haddad@germany.embassy.example | G3: Yes | H3: +91 11817 07536 | I3: Yes | J3: Initial Contact | K3: Priya Nair | L3: 46057 | M3: 46078 | N3: 46132 | O3: 1 | P3: Low | Q3: Email | R3: Intro call held | S3: COUNTRY_STD; STATUS_STD | T3: 3 | U3: =IF(OR(M3="",M3>Settings!$B$2),"",Settings!$B$2-M3) -> 223 | V3: =IF(AND(N3<>"",N3<Settings!$B$2,J3<>"Closed"),"Yes","No") -> Yes | W3: =IF(AND(OR(J3="Initial Contact",J3="In Discussion",J3="Meeting Scheduled",J3="Engaged"),ISNUMBER(U3),U3>Settings!$B$3),"Yes","No") -> Yes
A4: EMB-003 | B4: Italy | C4: Europe | D4: Kwame Okafor | E4: Counsellor (Public Affairs) | F4: kwame.okafor@italy.embassy.example | G4: Yes | H4: +91 11269 87168 | I4: Yes | J4: On Hold | K4: Neha Kulkarni | L4: 46079 | M4: 46143 | N4: 46257 | O4: 6 | P4: Not Recorded | Q4: Phone | R4: Awaiting HQ approval | S4: REGION_FILLED; ENG_MISSING | T4: 4 | U4: =IF(OR(M4="",M4>Settings!$B$2),"",Settings!$B$2-M4) -> 158 | V4: =IF(AND(N4<>"",N4<Settings!$B$2,J4<>"Closed"),"Yes","No") -> Yes | W4: =IF(AND(OR(J4="Initial Contact",J4="In Discussion",J4="Meeting Scheduled",J4="Engaged"),ISNUMBER(U4),U4>Settings!$B$3),"Yes","No") -> No
A5: EMB-004 | B5: Spain | C5: Europe | D5: Leila Bergstrom | E5: Protocol Officer | F5: leila.bergstrom@spain.embassy.example | G5: Yes | H5: +91 11373 17784 | I5: Yes | J5: Engaged | K5: Sameer Khan | L5: 46233 | M5: 46248 | N5: 46287 | O5: 19 | P5: High | Q5: Phone | R5: Regular quarterly touchpoints | T5: 5 | U5: =IF(OR(M5="",M5>Settings!$B$2),"",Settings!$B$2-M5) -> 53 | V5: =IF(AND(N5<>"",N5<Settings!$B$2,J5<>"Closed"),"Yes","No") -> Yes | W5: =IF(AND(OR(J5="Initial Contact",J5="In Discussion",J5="Meeting Scheduled",J5="Engaged"),ISNUMBER(U5),U5>Settings!$B$3),"Yes","No") -> No
A6: EMB-005 | B6: Portugal | C6: Europe | D6: Omar Khalil | E6: Counsellor (Public Affairs) | F6: omar.khalil@portugal.embassy.example | G6: Yes | H6: +91 97876 80457 | I6: Yes | J6: In Discussion | K6: Anita Deshmukh | L6: 46199 | M6: 46270 | N6: 46295 | O6: 8 | P6: Low | Q6: Official Letter | R6: Positive response | T6: 6 | U6: =IF(OR(M6="",M6>Settings!$B$2),"",Settings!$B$2-M6) -> 31 | V6: =IF(AND(N6<>"",N6<Settings!$B$2,J6<>"Closed"),"Yes","No") -> Yes | W6: =IF(AND(OR(J6="Initial Contact",J6="In Discussion",J6="Meeting Scheduled",J6="Engaged"),ISNUMBER(U6),U6>Settings!$B$3),"Yes","No") -> No
A7: EMB-006 | B7: Netherlands | C7: Europe | D7: Carla Alvarez | E7: Counsellor (Public Affairs) | F7: carla.alvarez@netherlands.embassy.example | G7: Yes | H7: +91 11819 33190 | I7: Yes | J7: Not Started | K7: Neha Kulkarni | M7: 46249 | O7: 2 | P7: N/A (Not Started) | Q7: N/A (Not Started) | R7: Contact details to be verified | S7: STATUS_STD; STATUS_CONFLICT | T7: 7 | U7: =IF(OR(M7="",M7>Settings!$B$2),"",Settings!$B$2-M7) -> 52 | V7: =IF(AND(N7<>"",N7<Settings!$B$2,J7<>"Closed"),"Yes","No") -> No | W7: =IF(AND(OR(J7="Initial Contact",J7="In Discussion",J7="Meeting Scheduled",J7="Engaged"),ISNUMBER(U7),U7>Settings!$B$3),"Yes","No") -> No
A8: EMB-007 | B8: Belgium | C8: Europe | D8: Amara Okafor | E8: Protocol Officer | F8: amara.okafor@belgium.embassy.example | G8: Yes | H8: +91 11499 72837 | I8: Yes | J8: Engaged | K8: Rahul Verma | L8: 45758 | M8: 46294 | N8: 46316 | P8: Medium | Q8: Event | R8: Regular quarterly touchpoints | S8: INTERACTIONS_MISSING | T8: 8 | U8: =IF(OR(M8="",M8>Settings!$B$2),"",Settings!$B$2-M8) -> 7 | V8: =IF(AND(N8<>"",N8<Settings!$B$2,J8<>"Closed"),"Yes","No") -> No | W8: =IF(AND(OR(J8="Initial Contact",J8="In Discussion",J8="Meeting Scheduled",J8="Engaged"),ISNUMBER(U8),U8>Settings!$B$3),"Yes","No") -> No
A9: EMB-008 | B9: Switzerland | C9: Europe | D9: Elena Rossi | E9: Protocol Officer | F9: elena.rossi@switzerland.embassy.example | G9: Yes | H9: +91 11447 51779 | I9: Yes | J9: Meeting Scheduled | K9: Rahul Verma | L9: 46204 | M9: 46280 | P9: Not Recorded | Q9: Official Letter | R9: Meeting with Ambassador pending | S9: ENG_MISSING; FOLLOWUP_MISSING; INTERACTIONS_MISSING | T9: 9 | U9: =IF(OR(M9="",M9>Settings!$B$2),"",Settings!$B$2-M9) -> 21 | V9: =IF(AND(N9<>"",N9<Settings!$B$2,J9<>"Closed"),"Yes","No") -> No | W9: =IF(AND(OR(J9="Initial Contact",J9="In Discussion",J9="Meeting Scheduled",J9="Engaged"),ISNUMBER(U9),U9>Settings!$B$3),"Yes","No") -> No
A10: EMB-009 | B10: Austria | C10: Europe | D10: Amara Petrov | E10: Second Secretary | G10: Missing | I10: No | J10: Not Started | K10: Unassigned | O10: 0 | P10: N/A (Not Started) | Q10: N/A (Not Started) | R10: Priority list - Q4 | S10: STATUS_STD; EMAIL_MISSING; PHONE_INVALID; OWNER_MISSING | T10: 10 | U10: =IF(OR(M10="",M10>Settings!$B$2),"",Settings!$B$2-M10) | V10: =IF(AND(N10<>"",N10<Settings!$B$2,J10<>"Closed"),"Yes","No") -> No | W10: =IF(AND(OR(J10="Initial Contact",J10="In Discussion",J10="Meeting Scheduled",J10="Engaged"),ISNUMBER(U10),U10>Settings!$B$3),"Yes","No") -> No
A11: EMB-010 | B11: Sweden | C11: Europe | D11: Joao Garcia | E11: Commercial Counsellor | F11: joao.garcia@sweden.embassy.example | G11: Yes | H11: +91 96425 24776 | I11: Yes | J11: Initial Contact | K11: Sameer Khan | L11: 46005 | O11: 2 | P11: Medium | Q11: Event | R11: Awaiting acknowledgement | S11: STATUS_STD; FOLLOWUP_MISSING | T11: 11 | U11: =IF(OR(M11="",M11>Settings!$B$2),"",Settings!$B$2-M11) | V11: =IF(AND(N11<>"",N11<Settings!$B$2,J11<>"Closed"),"Yes","No") -> No | W11: =IF(AND(OR(J11="Initial Contact",J11="In Discussion",J11="Meeting Scheduled",J11="Engaged"),ISNUMBER(U11),U11>Settings!$B$3),"Yes","No") -> No
A12: EMB-011 | B12: Norway | C12: Europe | D12: Diego Mensah | E12: Second Secretary | F12: diego.mensah@norway.embassy.example | G12: Yes | H12: +91 95258 98319 | I12: Yes | J12: On Hold | K12: Priya Nair | L12: 45891 | M12: 46233 | N12: 46310 | O12: 2 | P12: Low | Q12: Email | R12: Paused - elections | S12: DATE_TEXT | T12: 12 | U12: =IF(OR(M12="",M12>Settings!$B$2),"",Settings!$B$2-M12) -> 68 | V12: =IF(AND(N12<>"",N12<Settings!$B$2,J12<>"Closed"),"Yes","No") -> No | W12: =IF(AND(OR(J12="Initial Contact",J12="In Discussion",J12="Meeting Scheduled",J12="Engaged"),ISNUMBER(U12),U12>Settings!$B$3),"Yes","No") -> No
A13: EMB-012 | B13: Denmark | C13: Europe | D13: Mei Moreau | E13: First Secretary (Political) | F13: mei.moreau@denmark.embassy.example | G13: Yes | H13: +91 11814 52441 | I13: Yes | J13: Meeting Scheduled | K13: Sameer Khan | L13: 46096 | M13: 46195 | N13: 46215 | O13: 6 | P13: Medium | Q13: Email | R13: Date to be confirmed | T13: 13 | U13: =IF(OR(M13="",M13>Settings!$B$2),"",Settings!$B$2-M13) -> 106 | V13: =IF(AND(N13<>"",N13<Settings!$B$2,J13<>"Closed"),"Yes","No") -> Yes | W13: =IF(AND(OR(J13="Initial Contact",J13="In Discussion",J13="Meeting Scheduled",J13="Engaged"),ISNUMBER(U13),U13>Settings!$B$3),"Yes","No") -> Yes
A14: EMB-013 | B14: Finland | C14: Europe | D14: Stefan Petrov | E14: First Secretary (Political) | F14: stefan.petrov@finland.embassy.example | G14: Yes | H14: +91 11515 84645 | I14: Yes | J14: In Discussion | K14: Arjun Mehta | L14: 45696 | M14: 46289 | N14: 46321 | O14: 5 | P14: Medium | Q14: Email | R14: Positive response | T14: 14 | U14: =IF(OR(M14="",M14>Settings!$B$2),"",Settings!$B$2-M14) -> 12 | V14: =IF(AND(N14<>"",N14<Settings!$B$2,J14<>"Closed"),"Yes","No") -> No | W14: =IF(AND(OR(J14="Initial Contact",J14="In Discussion",J14="Meeting Scheduled",J14="Engaged"),ISNUMBER(U14),U14>Settings!$B$3),"Yes","No") -> No
A15: EMB-014 | B15: Poland | C15: Europe | D15: Aisha Tanaka | E15: Press & Information Officer | F15: aisha.tanaka@poland.embassy.example | G15: Yes | H15: +91 11494 06925 | I15: Yes | J15: Meeting Scheduled | K15: Sameer Khan | L15: 45917 | M15: 46383 | O15: 8 | P15: Medium | Q15: Phone | R15: Date to be confirmed | S15: DATE_FUTURE_LAST; FOLLOWUP_MISSING | T15: 15 | U15: =IF(OR(M15="",M15>Settings!$B$2),"",Settings!$B$2-M15) | V15: =IF(AND(N15<>"",N15<Settings!$B$2,J15<>"Closed"),"Yes","No") -> No | W15: =IF(AND(OR(J15="Initial Contact",J15="In Discussion",J15="Meeting Scheduled",J15="Engaged"),ISNUMBER(U15),U15>Settings!$B$3),"Yes","No") -> No
A16: EMB-015 | B16: Czechia | C16: Europe | D16: Sofia Larsen | E16: Counsellor (Public Affairs) | F16: sofia.larsen@czechrepubli.embassy.example | G16: Yes | H16: +91 99128 08458 | I16: Yes | J16: In Discussion | K16: Arjun Mehta | L16: 45729 | M16: 46269 | N16: 46323 | O16: 6 | P16: High | Q16: Official Letter | R16: Reviewing MoU wording | S16: REGION_STD | T16: 16 | U16: =IF(OR(M16="",M16>Settings!$B$2),"",Settings!$B$2-M16) -> 32 | V16: =IF(AND(N16<>"",N16<Settings!$B$2,J16<>"Closed"),"Yes","No") -> No | W16: =IF(AND(OR(J16="Initial Contact",J16="In Discussion",J16="Meeting Scheduled",J16="Engaged"),ISNUMBER(U16),U16>Settings!$B$3),"Yes","No") -> No
A17: EMB-016 | B17: Hungary | C17: Europe | D17: Fatima Moreau | E17: Cultural Attache | F17: fatima.moreau@hungary.embassy.example | G17: Yes | I17: Missing | J17: Initial Contact | K17: Arjun Mehta | L17: 45829 | M17: 46299 | O17: 2 | P17: Low | Q17: Official Letter | R17: Note verbale sent | S17: PHONE_MISSING; FOLLOWUP_MISSING | T17: 17 | U17: =IF(OR(M17="",M17>Settings!$B$2),"",Settings!$B$2-M17) -> 2 | V17: =IF(AND(N17<>"",N17<Settings!$B$2,J17<>"Closed"),"Yes","No") -> No | W17: =IF(AND(OR(J17="Initial Contact",J17="In Discussion",J17="Meeting Scheduled",J17="Engaged"),ISNUMBER(U17),U17>Settings!$B$3),"Yes","No") -> No
A18: EMB-017 | B18: Greece | C18: Europe | D18: Omar Alvarez | E18: First Secretary (Political) | F18: omar.alvarez@greece.embassy.example | G18: Yes | H18: +91 11266 88281 | I18: Yes | J18: Not Started | K18: Rahul Verma | O18: 0 | P18: N/A (Not Started) | Q18: N/A (Not Started) | R18: Priority list - Q4 | S18: REGION_FILLED | T18: 18 | U18: =IF(OR(M18="",M18>Settings!$B$2),"",Settings!$B$2-M18) | V18: =IF(AND(N18<>"",N18<Settings!$B$2,J18<>"Closed"),"Yes","No") -> No | W18: =IF(AND(OR(J18="Initial Contact",J18="In Discussion",J18="Meeting Scheduled",J18="Engaged"),ISNUMBER(U18),U18>Settings!$B$3),"Yes","No") -> No
A19: EMB-018 | B19: Ireland | C19: Europe | D19: Fatima Novak | E19: Cultural Attache | F19: fatima.novak@ireland.embassy.example | G19: Yes | H19: +91 11632 44845 | I19: Yes | J19: In Discussion | K19: Sameer Khan | L19: 45681 | M19: 46087 | N19: 46128 | O19: 0 | P19: Medium | Q19: Phone | R19: Draft proposal shared | S19: STATUS_CONFLICT | T19: 19 | U19: =IF(OR(M19="",M19>Settings!$B$2),"",Settings!$B$2-M19) -> 214 | V19: =IF(AND(N19<>"",N19<Settings!$B$2,J19<>"Closed"),"Yes","No") -> Yes | W19: =IF(AND(OR(J19="Initial Contact",J19="In Discussion",J19="Meeting Scheduled",J19="Engaged"),ISNUMBER(U19),U19>Settings!$B$3),"Yes","No") -> Yes
A20: EMB-019 | B20: UK | C20: Europe | D20: Amara Rossi | E20: Cultural Attache | F20: amara.rossi@unitedkingdo.embassy.example | G20: Yes | H20: +91 91543 82993 | I20: Yes | J20: On Hold | K20: Anita Deshmukh | L20: 46168 | M20: 46273 | N20: 46379 | O20: 4 | P20: Low | Q20: Event | R20: Awaiting HQ approval | S20: REGION_STD | T20: 20 | U20: =IF(OR(M20="",M20>Settings!$B$2),"",Settings!$B$2-M20) -> 28 | V20: =IF(AND(N20<>"",N20<Settings!$B$2,J20<>"Closed"),"Yes","No") -> No | W20: =IF(AND(OR(J20="Initial Contact",J20="In Discussion",J20="Meeting Scheduled",J20="Engaged"),ISNUMBER(U20),U20>Settings!$B$3),"Yes","No") -> No
A21: EMB-020 | B21: Russian Federation | C21: Europe | D21: Carla Alvarez | E21: Press & Information Officer | F21: carla.alvarez@russia.embassy.example | G21: Yes | H21: +91 11217 44325 | I21: Yes | J21: Engaged | K21: Neha Kulkarni | L21: 46002 | M21: 46083 | N21: 46122 | O21: 18 | P21: High | Q21: Event | R21: Regular quarterly touchpoints | T21: 21 | U21: =IF(OR(M21="",M21>Settings!$B$2),"",Settings!$B$2-M21) -> 218 | V21: =IF(AND(N21<>"",N21<Settings!$B$2,J21<>"Closed"),"Yes","No") -> Yes | W21: =IF(AND(OR(J21="Initial Contact",J21="In Discussion",J21="Meeting Scheduled",J21="Engaged"),ISNUMBER(U21),U21>Settings!$B$3),"Yes","No") -> Yes
A22: EMB-021 | B22: Japan | C22: Asia-Pacific | D22: Omar Larsen | E22: Counsellor (Public Affairs) | F22: omar.larsen@japan.embassy.example | G22: Yes | H22: +91 11626 45154 | I22: Yes | J22: Meeting Scheduled | K22: Sameer Khan | L22: 45820 | M22: 46252 | N22: 46280 | O22: 8 | P22: Medium | Q22: Meeting | R22: Date to be confirmed | S22: COUNTRY_STD; REGION_FILLED | T22: 22 | U22: =IF(OR(M22="",M22>Settings!$B$2),"",Settings!$B$2-M22) -> 49 | V22: =IF(AND(N22<>"",N22<Settings!$B$2,J22<>"Closed"),"Yes","No") -> Yes | W22: =IF(AND(OR(J22="Initial Contact",J22="In Discussion",J22="Meeting Scheduled",J22="Engaged"),ISNUMBER(U22),U22>Settings!$B$3),"Yes","No") -> No
A23: EMB-022 | B23: Korea (South) | C23: Asia-Pacific | D23: Sofia Silva | E23: Second Secretary | F23: sofia.silva@southkorea.embassy.example | G23: Yes | H23: +91 97883 65506 | I23: Yes | J23: Engaged | K23: Rahul Verma | L23: 45945 | M23: 46253 | N23: 46275 | O23: 0 | P23: Not Recorded | Q23: Meeting | R23: Embassy declined further participation | S23: ENG_MISSING; STATUS_CONFLICT | T23: 23 | U23: =IF(OR(M23="",M23>Settings!$B$2),"",Settings!$B$2-M23) -> 48 | V23: =IF(AND(N23<>"",N23<Settings!$B$2,J23<>"Closed"),"Yes","No") -> Yes | W23: =IF(AND(OR(J23="Initial Contact",J23="In Discussion",J23="Meeting Scheduled",J23="Engaged"),ISNUMBER(U23),U23>Settings!$B$3),"Yes","No") -> No
A24: EMB-023 | B24: China | C24: Asia-Pacific | D24: Fatima Moreau | E24: Second Secretary | F24: fatima.moreau@china.embassy.example | G24: Yes | H24: +91 11378 49518 | I24: Yes | J24: Engaged | K24: Rahul Verma | L24: 45769 | M24: 46292 | N24: 46335 | O24: 8 | P24: High | Q24: Email | R24: Active collaboration | T24: 24 | U24: =IF(OR(M24="",M24>Settings!$B$2),"",Settings!$B$2-M24) -> 9 | V24: =IF(AND(N24<>"",N24<Settings!$B$2,J24<>"Closed"),"Yes","No") -> No | W24: =IF(AND(OR(J24="Initial Contact",J24="In Discussion",J24="Meeting Scheduled",J24="Engaged"),ISNUMBER(U24),U24>Settings!$B$3),"Yes","No") -> No
A25: EMB-024 | B25: Indonesia | C25: Asia-Pacific | D25: Andrei Tanaka | E25: Protocol Officer | F25: andrei.tanaka@indonesia.embassy.example | G25: Yes | H25: +91 11783 75555 | I25: Yes | J25: Initial Contact | K25: Unassigned | L25: 46172 | M25: 46173 | N25: 46228 | O25: 2 | P25: Medium | Q25: Meeting | R25: Intro call held | S25: OWNER_MISSING | T25: 25 | U25: =IF(OR(M25="",M25>Settings!$B$2),"",Settings!$B$2-M25) -> 128 | V25: =IF(AND(N25<>"",N25<Settings!$B$2,J25<>"Closed"),"Yes","No") -> Yes | W25: =IF(AND(OR(J25="Initial Contact",J25="In Discussion",J25="Meeting Scheduled",J25="Engaged"),ISNUMBER(U25),U25>Settings!$B$3),"Yes","No") -> Yes
A26: EMB-025 | B26: Malaysia | C26: Asia-Pacific | D26: Nadia Tanaka | E26: Protocol Officer | F26: nadia.tanaka@malaysia.embassy.example | G26: Yes | I26: No | J26: Initial Contact | K26: Priya Nair | L26: 45997 | M26: 46246 | N26: 46271 | O26: 1 | P26: Medium | Q26: Meeting | R26: Note verbale sent | S26: PHONE_INVALID | T26: 26 | U26: =IF(OR(M26="",M26>Settings!$B$2),"",Settings!$B$2-M26) -> 55 | V26: =IF(AND(N26<>"",N26<Settings!$B$2,J26<>"Closed"),"Yes","No") -> Yes | W26: =IF(AND(OR(J26="Initial Contact",J26="In Discussion",J26="Meeting Scheduled",J26="Engaged"),ISNUMBER(U26),U26>Settings!$B$3),"Yes","No") -> No
A27: EMB-026 | B27: Singapore | C27: Asia-Pacific | D27: Omar Rossi | E27: Counsellor (Public Affairs) | F27: omar.rossi@singapore.embassy.example | G27: Yes | H27: +91 11368 82834 | I27: Yes | J27: Closed | K27: Arjun Mehta | L27: 45811 | M27: 46216 | O27: 2 | P27: Low | Q27: Email | R27: Declined - policy restrictions | S27: NEAR_DUP_KEPT | T27: 27 | U27: =IF(OR(M27="",M27>Settings!$B$2),"",Settings!$B$2-M27) -> 85 | V27: =IF(AND(N27<>"",N27<Settings!$B$2,J27<>"Closed"),"Yes","No") -> No | W27: =IF(AND(OR(J27="Initial Contact",J27="In Discussion",J27="Meeting Scheduled",J27="Engaged"),ISNUMBER(U27),U27>Settings!$B$3),"Yes","No") -> No
A28: EMB-027 | B28: Thailand | C28: Asia-Pacific | D28: Diego Alvarez | E28: Second Secretary | F28: diego.alvarez@thailand.embassy.example | G28: Yes | H28: +91 11704 42248 | I28: Yes | J28: Engaged | K28: Priya Nair | L28: 46140 | M28: 46277 | N28: 46294 | O28: 12 | P28: High | Q28: Event | R28: Co-hosted event in Q2 | T28: 28 | U28: =IF(OR(M28="",M28>Settings!$B$2),"",Settings!$B$2-M28) -> 24 | V28: =IF(AND(N28<>"",N28<Settings!$B$2,J28<>"Closed"),"Yes","No") -> Yes | W28: =IF(AND(OR(J28="Initial Contact",J28="In Discussion",J28="Meeting Scheduled",J28="Engaged"),ISNUMBER(U28),U28>Settings!$B$3),"Yes","No") -> No
A29: EMB-028 | B29: Vietnam | C29: Asia-Pacific | D29: Diego Garcia | E29: Commercial Counsellor | F29: diego.garcia@vietnam.embassy.example | G29: Yes | H29: +91 11428 07001 | I29: Yes | J29: Not Started | K29: Neha Kulkarni | M29: 46199 | O29: 1 | P29: N/A (Not Started) | Q29: N/A (Not Started) | R29: Contact details to be verified | S29: STATUS_CONFLICT | T29: 29 | U29: =IF(OR(M29="",M29>Settings!$B$2),"",Settings!$B$2-M29) -> 102 | V29: =IF(AND(N29<>"",N29<Settings!$B$2,J29<>"Closed"),"Yes","No") -> No | W29: =IF(AND(OR(J29="Initial Contact",J29="In Discussion",J29="Meeting Scheduled",J29="Engaged"),ISNUMBER(U29),U29>Settings!$B$3),"Yes","No") -> No
A30: EMB-029 | B30: Philippines | C30: Asia-Pacific | D30: Elena Mensah | E30: Second Secretary | F30: elena.mensah@philippines.embassy.example | G30: Yes | H30: +91 11816 63233 | I30: Yes | J30: In Discussion | K30: Sameer Khan | L30: 46053 | M30: 46272 | N30: 46313 | O30: 6 | P30: Medium | Q30: Email | R30: Draft proposal shared | T30: 30 | U30: =IF(OR(M30="",M30>Settings!$B$2),"",Settings!$B$2-M30) -> 29 | V30: =IF(AND(N30<>"",N30<Settings!$B$2,J30<>"Closed"),"Yes","No") -> No | W30: =IF(AND(OR(J30="Initial Contact",J30="In Discussion",J30="Meeting Scheduled",J30="Engaged"),ISNUMBER(U30),U30>Settings!$B$3),"Yes","No") -> No
A31: EMB-030 | B31: Australia | C31: Asia-Pacific | D31: Pavel Petrov | E31: Cultural Attache | F31: pavel.petrov@australia.embassy.example | G31: Yes | H31: +91 11259 21236 | I31: Yes | J31: On Hold | K31: Sameer Khan | L31: 46232 | M31: 46241 | N31: 46348 | O31: 6 | P31: Low | Q31: Event | R31: Embassy leadership change | S31: STATUS_STD | T31: 31 | U31: =IF(OR(M31="",M31>Settings!$B$2),"",Settings!$B$2-M31) -> 60 | V31: =IF(AND(N31<>"",N31<Settings!$B$2,J31<>"Closed"),"Yes","No") -> No | W31: =IF(AND(OR(J31="Initial Contact",J31="In Discussion",J31="Meeting Scheduled",J31="Engaged"),ISNUMBER(U31),U31>Settings!$B$3),"Yes","No") -> No
A32: EMB-031 | B32: New Zealand | C32: Asia-Pacific | D32: Kwame Yilmaz | E32: Press & Information Officer | F32: kwame.yilmaz@newzealand.embassy.example | G32: Yes | H32: +91 11790 85417 | I32: Yes | J32: Meeting Scheduled | K32: Priya Nair | L32: 46210 | M32: 46218 | N32: 46250 | O32: 8 | P32: Not Recorded | Q32: Phone | R32: Venue finalised | S32: ENG_MISSING | T32: 32 | U32: =IF(OR(M32="",M32>Settings!$B$2),"",Settings!$B$2-M32) -> 83 | V32: =IF(AND(N32<>"",N32<Settings!$B$2,J32<>"Closed"),"Yes","No") -> Yes | W32: =IF(AND(OR(J32="Initial Contact",J32="In Discussion",J32="Meeting Scheduled",J32="Engaged"),ISNUMBER(U32),U32>Settings!$B$3),"Yes","No") -> No
A33: EMB-032 | B33: Mongolia | C33: Asia-Pacific | D33: Elena Larsen | E33: First Secretary (Political) | F33: elena.larsen@mongolia.embassy.example | G33: Yes | H33: +91 92016 12840 | I33: Yes | J33: In Discussion | K33: Arjun Mehta | L33: 46205 | N33: 46307 | O33: 5 | P33: Medium | Q33: Phone | R33: Exploring joint programme | T33: 33 | U33: =IF(OR(M33="",M33>Settings!$B$2),"",Settings!$B$2-M33) | V33: =IF(AND(N33<>"",N33<Settings!$B$2,J33<>"Closed"),"Yes","No") -> No | W33: =IF(AND(OR(J33="Initial Contact",J33="In Discussion",J33="Meeting Scheduled",J33="Engaged"),ISNUMBER(U33),U33>Settings!$B$3),"Yes","No") -> No
A34: EMB-033 | B34: Myanmar | C34: Asia-Pacific | D34: Stefan Mensah | E34: First Secretary (Political) | F34: stefan.mensah@myanmar | G34: No | H34: +91 11819 79678 | I34: Yes | J34: In Discussion | K34: Sameer Khan | L34: 46065 | M34: 46236 | N34: 46279 | O34: 5 | P34: Medium | Q34: Meeting | R34: Draft proposal shared | S34: STATUS_STD; DATE_TEXT; EMAIL_INVALID | T34: 34 | U34: =IF(OR(M34="",M34>Settings!$B$2),"",Settings!$B$2-M34) -> 65 | V34: =IF(AND(N34<>"",N34<Settings!$B$2,J34<>"Closed"),"Yes","No") -> Yes | W34: =IF(AND(OR(J34="Initial Contact",J34="In Discussion",J34="Meeting Scheduled",J34="Engaged"),ISNUMBER(U34),U34>Settings!$B$3),"Yes","No") -> No
A35: EMB-034 | B35: Cambodia | C35: Asia-Pacific | D35: Mei Silva | E35: Counsellor (Public Affairs) | F35: mei.silva@cambodia.embassy.example | G35: Yes | H35: +91 11839 18276 | I35: Yes | J35: In Discussion | K35: Unassigned | L35: 46097 | M35: 46299 | N35: 46328 | O35: 3 | P35: Low | Q35: Email | R35: Embassy declined further participation | S35: OWNER_MISSING | T35: 35 | U35: =IF(OR(M35="",M35>Settings!$B$2),"",Settings!$B$2-M35) -> 2 | V35: =IF(AND(N35<>"",N35<Settings!$B$2,J35<>"Closed"),"Yes","No") -> No | W35: =IF(AND(OR(J35="Initial Contact",J35="In Discussion",J35="Meeting Scheduled",J35="Engaged"),ISNUMBER(U35),U35>Settings!$B$3),"Yes","No") -> No
A36: EMB-035 | B36: UAE | C36: Middle East & North Africa | D36: Leila Nguyen | E36: Second Secretary | F36: leila.nguyen@unitedarabem.embassy.example | G36: Yes | H36: +91 11580 57803 | I36: Yes | J36: On Hold | K36: Arjun Mehta | L36: 45720 | M36: 46294 | N36: 46395 | O36: 4 | P36: Low | Q36: Email | R36: Awaiting HQ approval | S36: STATUS_STD | T36: 36 | U36: =IF(OR(M36="",M36>Settings!$B$2),"",Settings!$B$2-M36) -> 7 | V36: =IF(AND(N36<>"",N36<Settings!$B$2,J36<>"Closed"),"Yes","No") -> No | W36: =IF(AND(OR(J36="Initial Contact",J36="In Discussion",J36="Meeting Scheduled",J36="Engaged"),ISNUMBER(U36),U36>Settings!$B$3),"Yes","No") -> No
A37: EMB-036 | B37: Saudi Arabia | C37: Middle East & North Africa | D37: Nadia Nguyen | E37: First Secretary (Political) | F37: nadia.nguyen@saudiarabia.embassy.example | G37: Yes | H37: +91 11808 53867 | I37: Yes | J37: Meeting Scheduled | K37: Rahul Verma | L37: 45687 | M37: 46282 | N37: 46301 | O37: 8 | P37: High | Q37: Official Letter | R37: Meeting with Ambassador pending | S37: REGION_STD | T37: 37 | U37: =IF(OR(M37="",M37>Settings!$B$2),"",Settings!$B$2-M37) -> 19 | V37: =IF(AND(N37<>"",N37<Settings!$B$2,J37<>"Closed"),"Yes","No") -> No | W37: =IF(AND(OR(J37="Initial Contact",J37="In Discussion",J37="Meeting Scheduled",J37="Engaged"),ISNUMBER(U37),U37>Settings!$B$3),"Yes","No") -> No
A38: EMB-037 | B38: Qatar | C38: Middle East & North Africa | D38: Carla Haddad | E38: Cultural Attache | F38: carla.haddad@qatar.embassy.example | G38: Yes | H38: +91 11229 83725 | I38: Yes | J38: Engaged | K38: Sameer Khan | L38: 45814 | M38: 46287 | N38: 46306 | O38: 16 | P38: High | Q38: Meeting | R38: Active collaboration | T38: 38 | U38: =IF(OR(M38="",M38>Settings!$B$2),"",Settings!$B$2-M38) -> 14 | V38: =IF(AND(N38<>"",N38<Settings!$B$2,J38<>"Closed"),"Yes","No") -> No | W38: =IF(AND(OR(J38="Initial Contact",J38="In Discussion",J38="Meeting Scheduled",J38="Engaged"),ISNUMBER(U38),U38>Settings!$B$3),"Yes","No") -> No
A39: EMB-038 | B39: Kuwait | C39: Middle East & North Africa | D39: Yuki Zhang | E39: Second Secretary | F39: yuki.zhang@kuwait.embassy.example | G39: Yes | H39: +91 99992 48005 | I39: Yes | J39: Initial Contact | K39: Rahul Verma | L39: 45771 | M39: 46332 | N39: 46308 | O39: 2 | P39: Low | Q39: Official Letter | R39: Note verbale sent | S39: DATE_FUTURE_LAST; FOLLOWUP_BEFORE_LAST | T39: 39 | U39: =IF(OR(M39="",M39>Settings!$B$2),"",Settings!$B$2-M39) | V39: =IF(AND(N39<>"",N39<Settings!$B$2,J39<>"Closed"),"Yes","No") -> No | W39: =IF(AND(OR(J39="Initial Contact",J39="In Discussion",J39="Meeting Scheduled",J39="Engaged"),ISNUMBER(U39),U39>Settings!$B$3),"Yes","No") -> No
A40: EMB-039 | B40: Oman | C40: Middle East & North Africa | D40: Amara Rossi | E40: Press & Information Officer | F40: amara.rossi@oman.embassy.example | G40: Yes | H40: +91 11213 57164 | I40: Yes | J40: In Discussion | K40: Unassigned | L40: 45928 | M40: 46280 | N40: 46320 | O40: 5 | P40: Not Recorded | Q40: Meeting | R40: Reviewing MoU wording | S40: OWNER_MISSING; ENG_MISSING | T40: 40 | U40: =IF(OR(M40="",M40>Settings!$B$2),"",Settings!$B$2-M40) -> 21 | V40: =IF(AND(N40<>"",N40<Settings!$B$2,J40<>"Closed"),"Yes","No") -> No | W40: =IF(AND(OR(J40="Initial Contact",J40="In Discussion",J40="Meeting Scheduled",J40="Engaged"),ISNUMBER(U40),U40>Settings!$B$3),"Yes","No") -> No
...

Sheet Removed_Rows
A1: Source_Row (Raw_Data) | B1: Embassy_ID | C1: Country | D1: Contact_Person | E1: Outreach_Status | F1: Reason removed
A2: 86 | B2: EMB-066 | C2: Brazil | D2: Amara Kim | E2: Initial Contact | F2: Exact duplicate of an earlier row (same ID, country, contact)
A3: 87 | B3: EMB-010 | C3: Sweden | D3: Joao Garcia | E3: Initial Contact Made | F3: Exact duplicate of an earlier row (same ID, country, contact)
A4: 88 | B4: EMB-051 | C4: Kenya | D4: Joao Nguyen | E4: Not Started | F4: Exact duplicate of an earlier row (same ID, country, contact)
A5: 89 | B5: EMB-037 | C5: Qatar | D5: Carla Haddad | E5: Engaged | F5: Exact duplicate of an earlier row (same ID, country, contact)
A6: 90 | B6: EMB-094 | C6: Mexico | D6: Pedro Nguyen | E6: Engaged | F6: Near-duplicate: same country, email, dates and counts as an earlier record under a different ID/contact
A7: 91 | B7: EMB-095 | C7: Singapore | D7: Tariq Kim | E7: Closed | F7: Near-duplicate: same country, email, dates and counts as an earlier record under a different ID/contact
A8: 92 | B8: EMB-096 | C8: GHANA | D8: Aisha Zhang | E8: Engaged | F8: Near-duplicate: same country, email, dates and counts as an earlier record under a different ID/contact

Sheet Cleaning_Log
A1: Cleaning Log - every change made between Raw_Data and Clean_Data
A3: Flag code | B3: Field | C3: Issue found | D3: Action taken | E3: Rows affected
A4: (removed) | B4: All | C4: Exact duplicate rows (EMB-010, 037, 051, 066) and near-duplicates (Mexico, Ghana, Singapore re-entered under new IDs/contacts) | D4: Removed from Clean_Data, listed on Removed_Rows; original record kept | E4: =COUNTA(Removed_Rows!A2:A100) -> 7
A5: NEAR_DUP_KEPT | B5: All | C5: Original record of a country that had a near-duplicate - contact needs confirming with the owner | D5: Kept; flagged for review | E5: =COUNTIF(Clean_Data!$S:$S,"*NEAR_DUP_KEPT*") -> 3
A6: ID_INFERRED | B6: Embassy_ID | C6: Missing ID (Senegal, USA) | D6: Filled from the ID sequence (EMB-060, EMB-063); to be confirmed | E6: =COUNTIF(Clean_Data!$S:$S,"*ID_INFERRED*") -> 2
A7: COUNTRY_STD | B7: Country | C7: Case / spacing (" Germany", "france", "GHANA") | D7: Trimmed and title-cased | E7: =COUNTIF(Clean_Data!$S:$S,"*COUNTRY_STD*") -> 3
A8: REGION_STD | B8: Region | C8: Variant spellings (europe, Sub Saharan Africa, N. America, MENA) | D8: Mapped to 6 standard regions | E8: =COUNTIF(Clean_Data!$S:$S,"*REGION_STD*") -> 8
A9: REGION_FILLED | B9: Region | C9: Blank region | D9: Filled from country (Italy, Greece -> Europe; Japan -> Asia-Pacific; Israel -> MENA; Cuba -> Americas) | E9: =COUNTIF(Clean_Data!$S:$S,"*REGION_FILLED*") -> 5
A10: REGION_REVIEW | B10: Region | C10: Kazakhstan sits in Asia-Pacific while other Central Asian states are in South & Central Asia | D10: Left as recorded; flagged for a regional-mapping decision | E10: =COUNTIF(Clean_Data!$S:$S,"*REGION_REVIEW*") -> 1
A11: STATUS_STD | B11: Outreach_Status | C11: 15 spellings for 7 statuses (Hold / On Hold, Initial Contact Made, lower-case) | D11: Standardised to: Not Started, Initial Contact, In Discussion, Meeting Scheduled, Engaged, On Hold, Closed | E11: =COUNTIF(Clean_Data!$S:$S,"*STATUS_STD*") -> 13
A12: DATE_TEXT | B12: Dates | C12: Dates stored as text (dd/mm/yyyy or yyyy-mm-dd) | D12: Converted to real dates (dd/mm/yyyy read as day-first) | E12: =COUNTIF(Clean_Data!$S:$S,"*DATE_TEXT*") -> 8
A13: DATE_ORDER | B13: Dates | C13: Last contact earlier than first contact | D13: Kept as recorded; flagged (needs source check) | E13: =COUNTIF(Clean_Data!$S:$S,"*DATE_ORDER*") -> 4
A14: DATE_FUTURE_FIRST | B14: Dates | C14: First contact date later than the as-of date | D14: Kept; flagged | E14: =COUNTIF(Clean_Data!$S:$S,"*DATE_FUTURE_FIRST*") -> 1
A15: DATE_FUTURE_LAST | B15: Dates | C15: Last contact date later than the as-of date (e.g. 01-Jan-2027) | D15: Kept; Days_Since_Last_Contact left blank for these; flagged | E15: =COUNTIF(Clean_Data!$S:$S,"*DATE_FUTURE_LAST*") -> 3
A16: FOLLOWUP_BEFORE_LAST | B16: Dates | C16: Next follow-up date earlier than last contact date | D16: Kept; flagged | E16: =COUNTIF(Clean_Data!$S:$S,"*FOLLOWUP_BEFORE_LAST*") -> 2
A17: INTERACTIONS_NEG | B17: Interactions | C17: Negative interaction count (-3) | D17: Set to blank (true value unknown); flagged | E17: =COUNTIF(Clean_Data!$S:$S,"*INTERACTIONS_NEG*") -> 1
A18: INTERACTIONS_MISSING | B18: Interactions | C18: Blank interaction count on an active embassy | D18: Left blank (not assumed to be 0); flagged | E18: =COUNTIF(Clean_Data!$S:$S,"*INTERACTIONS_MISSING*") -> 5
